2025-06-23 06:47:38,435 ERROR scheduler Exception in Enqueue Events for Site site1.localhost
Traceback (most recent call last):
  File "/home/frappe/frappe-bench/apps/frappe/frappe/utils/scheduler.py", line 99, in enqueue_events_for_site
    if is_scheduler_inactive():
       ^^^^^^^^^^^^^^^^^^^^^^^
  File "/home/frappe/frappe-bench/apps/frappe/frappe/utils/scheduler.py", line 143, in is_scheduler_inactive
    if is_scheduler_disabled(verbose=verbose):
       ^^^^^^^^^^^^^^^^^^^^^^^^^^^^^^^^^^^^^^
  File "/home/frappe/frappe-bench/apps/frappe/frappe/utils/scheduler.py", line 156, in is_scheduler_disabled
    frappe.db.get_single_value("System Settings", "enable_scheduler")
  File "/home/frappe/frappe-bench/apps/frappe/frappe/database/database.py", line 837, in get_single_value
    ).run()
      ^^^^^
  File "/home/frappe/frappe-bench/apps/frappe/frappe/query_builder/utils.py", line 87, in execute_query
    result = frappe.db.sql(query, params, *args, **kwargs)  # nosemgrep
             ^^^^^^^^^^^^^^^^^^^^^^^^^^^^^^^^^^^^^^^^^^^^^
  File "/home/frappe/frappe-bench/apps/frappe/frappe/database/database.py", line 207, in sql
    self.connect()
  File "/home/frappe/frappe-bench/apps/frappe/frappe/database/database.py", line 112, in connect
    self._conn: "MariadbConnection" | "PostgresConnection" = self.get_connection()
                                                             ^^^^^^^^^^^^^^^^^^^^^
  File "/home/frappe/frappe-bench/apps/frappe/frappe/database/mariadb/database.py", line 108, in get_connection
    conn = self._get_connection()
           ^^^^^^^^^^^^^^^^^^^^^^
  File "/home/frappe/frappe-bench/apps/frappe/frappe/database/mariadb/database.py", line 114, in _get_connection
    return self.create_connection()
           ^^^^^^^^^^^^^^^^^^^^^^^^
  File "/home/frappe/frappe-bench/apps/frappe/frappe/database/mariadb/database.py", line 117, in create_connection
    return pymysql.connect(**self.get_connection_settings())
           ^^^^^^^^^^^^^^^^^^^^^^^^^^^^^^^^^^^^^^^^^^^^^^^^^
  File "/home/frappe/frappe-bench/env/lib/python3.11/site-packages/pymysql/connections.py", line 361, in __init__
    self.connect()
  File "/home/frappe/frappe-bench/env/lib/python3.11/site-packages/pymysql/connections.py", line 669, in connect
    self._request_authentication()
  File "/home/frappe/frappe-bench/env/lib/python3.11/site-packages/pymysql/connections.py", line 957, in _request_authentication
    auth_packet = self._read_packet()
                  ^^^^^^^^^^^^^^^^^^^
  File "/home/frappe/frappe-bench/env/lib/python3.11/site-packages/pymysql/connections.py", line 775, in _read_packet
    packet.raise_for_error()
  File "/home/frappe/frappe-bench/env/lib/python3.11/site-packages/pymysql/protocol.py", line 219, in raise_for_error
    err.raise_mysql_exception(self._data)
  File "/home/frappe/frappe-bench/env/lib/python3.11/site-packages/pymysql/err.py", line 150, in raise_mysql_exception
    raise errorclass(errno, errval)
pymysql.err.OperationalError: (1045, "Access denied for user '_e1ef3e0c4bdfa786'@'172.18.0.4' (using password: YES)")
2025-06-23 06:48:39,659 ERROR scheduler Exception in Enqueue Events for Site site1.localhost
Traceback (most recent call last):
  File "/home/frappe/frappe-bench/apps/frappe/frappe/utils/scheduler.py", line 99, in enqueue_events_for_site
    if is_scheduler_inactive():
       ^^^^^^^^^^^^^^^^^^^^^^^
  File "/home/frappe/frappe-bench/apps/frappe/frappe/utils/scheduler.py", line 143, in is_scheduler_inactive
    if is_scheduler_disabled(verbose=verbose):
       ^^^^^^^^^^^^^^^^^^^^^^^^^^^^^^^^^^^^^^
  File "/home/frappe/frappe-bench/apps/frappe/frappe/utils/scheduler.py", line 156, in is_scheduler_disabled
    frappe.db.get_single_value("System Settings", "enable_scheduler")
  File "/home/frappe/frappe-bench/apps/frappe/frappe/database/database.py", line 837, in get_single_value
    ).run()
      ^^^^^
  File "/home/frappe/frappe-bench/apps/frappe/frappe/query_builder/utils.py", line 87, in execute_query
    result = frappe.db.sql(query, params, *args, **kwargs)  # nosemgrep
             ^^^^^^^^^^^^^^^^^^^^^^^^^^^^^^^^^^^^^^^^^^^^^
  File "/home/frappe/frappe-bench/apps/frappe/frappe/database/database.py", line 207, in sql
    self.connect()
  File "/home/frappe/frappe-bench/apps/frappe/frappe/database/database.py", line 112, in connect
    self._conn: "MariadbConnection" | "PostgresConnection" = self.get_connection()
                                                             ^^^^^^^^^^^^^^^^^^^^^
  File "/home/frappe/frappe-bench/apps/frappe/frappe/database/mariadb/database.py", line 108, in get_connection
    conn = self._get_connection()
           ^^^^^^^^^^^^^^^^^^^^^^
  File "/home/frappe/frappe-bench/apps/frappe/frappe/database/mariadb/database.py", line 114, in _get_connection
    return self.create_connection()
           ^^^^^^^^^^^^^^^^^^^^^^^^
  File "/home/frappe/frappe-bench/apps/frappe/frappe/database/mariadb/database.py", line 117, in create_connection
    return pymysql.connect(**self.get_connection_settings())
           ^^^^^^^^^^^^^^^^^^^^^^^^^^^^^^^^^^^^^^^^^^^^^^^^^
  File "/home/frappe/frappe-bench/env/lib/python3.11/site-packages/pymysql/connections.py", line 361, in __init__
    self.connect()
  File "/home/frappe/frappe-bench/env/lib/python3.11/site-packages/pymysql/connections.py", line 669, in connect
    self._request_authentication()
  File "/home/frappe/frappe-bench/env/lib/python3.11/site-packages/pymysql/connections.py", line 957, in _request_authentication
    auth_packet = self._read_packet()
                  ^^^^^^^^^^^^^^^^^^^
  File "/home/frappe/frappe-bench/env/lib/python3.11/site-packages/pymysql/connections.py", line 775, in _read_packet
    packet.raise_for_error()
  File "/home/frappe/frappe-bench/env/lib/python3.11/site-packages/pymysql/protocol.py", line 219, in raise_for_error
    err.raise_mysql_exception(self._data)
  File "/home/frappe/frappe-bench/env/lib/python3.11/site-packages/pymysql/err.py", line 150, in raise_mysql_exception
    raise errorclass(errno, errval)
pymysql.err.OperationalError: (1045, "Access denied for user '_e1ef3e0c4bdfa786'@'172.18.0.4' (using password: YES)")
2025-06-23 06:49:41,675 ERROR scheduler Exception in Enqueue Events for Site site1.localhost
Traceback (most recent call last):
  File "/home/frappe/frappe-bench/apps/frappe/frappe/utils/scheduler.py", line 99, in enqueue_events_for_site
    if is_scheduler_inactive():
       ^^^^^^^^^^^^^^^^^^^^^^^
  File "/home/frappe/frappe-bench/apps/frappe/frappe/utils/scheduler.py", line 143, in is_scheduler_inactive
    if is_scheduler_disabled(verbose=verbose):
       ^^^^^^^^^^^^^^^^^^^^^^^^^^^^^^^^^^^^^^
  File "/home/frappe/frappe-bench/apps/frappe/frappe/utils/scheduler.py", line 156, in is_scheduler_disabled
    frappe.db.get_single_value("System Settings", "enable_scheduler")
  File "/home/frappe/frappe-bench/apps/frappe/frappe/database/database.py", line 837, in get_single_value
    ).run()
      ^^^^^
  File "/home/frappe/frappe-bench/apps/frappe/frappe/query_builder/utils.py", line 87, in execute_query
    result = frappe.db.sql(query, params, *args, **kwargs)  # nosemgrep
             ^^^^^^^^^^^^^^^^^^^^^^^^^^^^^^^^^^^^^^^^^^^^^
  File "/home/frappe/frappe-bench/apps/frappe/frappe/database/database.py", line 207, in sql
    self.connect()
  File "/home/frappe/frappe-bench/apps/frappe/frappe/database/database.py", line 112, in connect
    self._conn: "MariadbConnection" | "PostgresConnection" = self.get_connection()
                                                             ^^^^^^^^^^^^^^^^^^^^^
  File "/home/frappe/frappe-bench/apps/frappe/frappe/database/mariadb/database.py", line 108, in get_connection
    conn = self._get_connection()
           ^^^^^^^^^^^^^^^^^^^^^^
  File "/home/frappe/frappe-bench/apps/frappe/frappe/database/mariadb/database.py", line 114, in _get_connection
    return self.create_connection()
           ^^^^^^^^^^^^^^^^^^^^^^^^
  File "/home/frappe/frappe-bench/apps/frappe/frappe/database/mariadb/database.py", line 117, in create_connection
    return pymysql.connect(**self.get_connection_settings())
           ^^^^^^^^^^^^^^^^^^^^^^^^^^^^^^^^^^^^^^^^^^^^^^^^^
  File "/home/frappe/frappe-bench/env/lib/python3.11/site-packages/pymysql/connections.py", line 361, in __init__
    self.connect()
  File "/home/frappe/frappe-bench/env/lib/python3.11/site-packages/pymysql/connections.py", line 669, in connect
    self._request_authentication()
  File "/home/frappe/frappe-bench/env/lib/python3.11/site-packages/pymysql/connections.py", line 957, in _request_authentication
    auth_packet = self._read_packet()
                  ^^^^^^^^^^^^^^^^^^^
  File "/home/frappe/frappe-bench/env/lib/python3.11/site-packages/pymysql/connections.py", line 775, in _read_packet
    packet.raise_for_error()
  File "/home/frappe/frappe-bench/env/lib/python3.11/site-packages/pymysql/protocol.py", line 219, in raise_for_error
    err.raise_mysql_exception(self._data)
  File "/home/frappe/frappe-bench/env/lib/python3.11/site-packages/pymysql/err.py", line 150, in raise_mysql_exception
    raise errorclass(errno, errval)
pymysql.err.OperationalError: (1045, "Access denied for user '_e1ef3e0c4bdfa786'@'172.18.0.4' (using password: YES)")
2025-06-23 06:50:43,905 ERROR scheduler Exception in Enqueue Events for Site site1.localhost
Traceback (most recent call last):
  File "/home/frappe/frappe-bench/apps/frappe/frappe/utils/scheduler.py", line 99, in enqueue_events_for_site
    if is_scheduler_inactive():
       ^^^^^^^^^^^^^^^^^^^^^^^
  File "/home/frappe/frappe-bench/apps/frappe/frappe/utils/scheduler.py", line 143, in is_scheduler_inactive
    if is_scheduler_disabled(verbose=verbose):
       ^^^^^^^^^^^^^^^^^^^^^^^^^^^^^^^^^^^^^^
  File "/home/frappe/frappe-bench/apps/frappe/frappe/utils/scheduler.py", line 156, in is_scheduler_disabled
    frappe.db.get_single_value("System Settings", "enable_scheduler")
  File "/home/frappe/frappe-bench/apps/frappe/frappe/database/database.py", line 837, in get_single_value
    ).run()
      ^^^^^
  File "/home/frappe/frappe-bench/apps/frappe/frappe/query_builder/utils.py", line 87, in execute_query
    result = frappe.db.sql(query, params, *args, **kwargs)  # nosemgrep
             ^^^^^^^^^^^^^^^^^^^^^^^^^^^^^^^^^^^^^^^^^^^^^
  File "/home/frappe/frappe-bench/apps/frappe/frappe/database/database.py", line 207, in sql
    self.connect()
  File "/home/frappe/frappe-bench/apps/frappe/frappe/database/database.py", line 112, in connect
    self._conn: "MariadbConnection" | "PostgresConnection" = self.get_connection()
                                                             ^^^^^^^^^^^^^^^^^^^^^
  File "/home/frappe/frappe-bench/apps/frappe/frappe/database/mariadb/database.py", line 108, in get_connection
    conn = self._get_connection()
           ^^^^^^^^^^^^^^^^^^^^^^
  File "/home/frappe/frappe-bench/apps/frappe/frappe/database/mariadb/database.py", line 114, in _get_connection
    return self.create_connection()
           ^^^^^^^^^^^^^^^^^^^^^^^^
  File "/home/frappe/frappe-bench/apps/frappe/frappe/database/mariadb/database.py", line 117, in create_connection
    return pymysql.connect(**self.get_connection_settings())
           ^^^^^^^^^^^^^^^^^^^^^^^^^^^^^^^^^^^^^^^^^^^^^^^^^
  File "/home/frappe/frappe-bench/env/lib/python3.11/site-packages/pymysql/connections.py", line 361, in __init__
    self.connect()
  File "/home/frappe/frappe-bench/env/lib/python3.11/site-packages/pymysql/connections.py", line 669, in connect
    self._request_authentication()
  File "/home/frappe/frappe-bench/env/lib/python3.11/site-packages/pymysql/connections.py", line 957, in _request_authentication
    auth_packet = self._read_packet()
                  ^^^^^^^^^^^^^^^^^^^
  File "/home/frappe/frappe-bench/env/lib/python3.11/site-packages/pymysql/connections.py", line 775, in _read_packet
    packet.raise_for_error()
  File "/home/frappe/frappe-bench/env/lib/python3.11/site-packages/pymysql/protocol.py", line 219, in raise_for_error
    err.raise_mysql_exception(self._data)
  File "/home/frappe/frappe-bench/env/lib/python3.11/site-packages/pymysql/err.py", line 150, in raise_mysql_exception
    raise errorclass(errno, errval)
pymysql.err.OperationalError: (1045, "Access denied for user '_e1ef3e0c4bdfa786'@'172.18.0.4' (using password: YES)")
2025-06-23 06:51:44,886 ERROR scheduler Exception in Enqueue Events for Site site1.localhost
Traceback (most recent call last):
  File "/home/frappe/frappe-bench/apps/frappe/frappe/utils/scheduler.py", line 99, in enqueue_events_for_site
    if is_scheduler_inactive():
       ^^^^^^^^^^^^^^^^^^^^^^^
  File "/home/frappe/frappe-bench/apps/frappe/frappe/utils/scheduler.py", line 143, in is_scheduler_inactive
    if is_scheduler_disabled(verbose=verbose):
       ^^^^^^^^^^^^^^^^^^^^^^^^^^^^^^^^^^^^^^
  File "/home/frappe/frappe-bench/apps/frappe/frappe/utils/scheduler.py", line 156, in is_scheduler_disabled
    frappe.db.get_single_value("System Settings", "enable_scheduler")
  File "/home/frappe/frappe-bench/apps/frappe/frappe/database/database.py", line 837, in get_single_value
    ).run()
      ^^^^^
  File "/home/frappe/frappe-bench/apps/frappe/frappe/query_builder/utils.py", line 87, in execute_query
    result = frappe.db.sql(query, params, *args, **kwargs)  # nosemgrep
             ^^^^^^^^^^^^^^^^^^^^^^^^^^^^^^^^^^^^^^^^^^^^^
  File "/home/frappe/frappe-bench/apps/frappe/frappe/database/database.py", line 207, in sql
    self.connect()
  File "/home/frappe/frappe-bench/apps/frappe/frappe/database/database.py", line 112, in connect
    self._conn: "MariadbConnection" | "PostgresConnection" = self.get_connection()
                                                             ^^^^^^^^^^^^^^^^^^^^^
  File "/home/frappe/frappe-bench/apps/frappe/frappe/database/mariadb/database.py", line 108, in get_connection
    conn = self._get_connection()
           ^^^^^^^^^^^^^^^^^^^^^^
  File "/home/frappe/frappe-bench/apps/frappe/frappe/database/mariadb/database.py", line 114, in _get_connection
    return self.create_connection()
           ^^^^^^^^^^^^^^^^^^^^^^^^
  File "/home/frappe/frappe-bench/apps/frappe/frappe/database/mariadb/database.py", line 117, in create_connection
    return pymysql.connect(**self.get_connection_settings())
           ^^^^^^^^^^^^^^^^^^^^^^^^^^^^^^^^^^^^^^^^^^^^^^^^^
  File "/home/frappe/frappe-bench/env/lib/python3.11/site-packages/pymysql/connections.py", line 361, in __init__
    self.connect()
  File "/home/frappe/frappe-bench/env/lib/python3.11/site-packages/pymysql/connections.py", line 669, in connect
    self._request_authentication()
  File "/home/frappe/frappe-bench/env/lib/python3.11/site-packages/pymysql/connections.py", line 957, in _request_authentication
    auth_packet = self._read_packet()
                  ^^^^^^^^^^^^^^^^^^^
  File "/home/frappe/frappe-bench/env/lib/python3.11/site-packages/pymysql/connections.py", line 775, in _read_packet
    packet.raise_for_error()
  File "/home/frappe/frappe-bench/env/lib/python3.11/site-packages/pymysql/protocol.py", line 219, in raise_for_error
    err.raise_mysql_exception(self._data)
  File "/home/frappe/frappe-bench/env/lib/python3.11/site-packages/pymysql/err.py", line 150, in raise_mysql_exception
    raise errorclass(errno, errval)
pymysql.err.OperationalError: (1045, "Access denied for user '_e1ef3e0c4bdfa786'@'172.18.0.4' (using password: YES)")
2025-06-23 06:52:47,067 ERROR scheduler Exception in Enqueue Events for Site site1.localhost
Traceback (most recent call last):
  File "/home/frappe/frappe-bench/apps/frappe/frappe/utils/scheduler.py", line 99, in enqueue_events_for_site
    if is_scheduler_inactive():
       ^^^^^^^^^^^^^^^^^^^^^^^
  File "/home/frappe/frappe-bench/apps/frappe/frappe/utils/scheduler.py", line 143, in is_scheduler_inactive
    if is_scheduler_disabled(verbose=verbose):
       ^^^^^^^^^^^^^^^^^^^^^^^^^^^^^^^^^^^^^^
  File "/home/frappe/frappe-bench/apps/frappe/frappe/utils/scheduler.py", line 156, in is_scheduler_disabled
    frappe.db.get_single_value("System Settings", "enable_scheduler")
  File "/home/frappe/frappe-bench/apps/frappe/frappe/database/database.py", line 837, in get_single_value
    ).run()
      ^^^^^
  File "/home/frappe/frappe-bench/apps/frappe/frappe/query_builder/utils.py", line 87, in execute_query
    result = frappe.db.sql(query, params, *args, **kwargs)  # nosemgrep
             ^^^^^^^^^^^^^^^^^^^^^^^^^^^^^^^^^^^^^^^^^^^^^
  File "/home/frappe/frappe-bench/apps/frappe/frappe/database/database.py", line 207, in sql
    self.connect()
  File "/home/frappe/frappe-bench/apps/frappe/frappe/database/database.py", line 112, in connect
    self._conn: "MariadbConnection" | "PostgresConnection" = self.get_connection()
                                                             ^^^^^^^^^^^^^^^^^^^^^
  File "/home/frappe/frappe-bench/apps/frappe/frappe/database/mariadb/database.py", line 108, in get_connection
    conn = self._get_connection()
           ^^^^^^^^^^^^^^^^^^^^^^
  File "/home/frappe/frappe-bench/apps/frappe/frappe/database/mariadb/database.py", line 114, in _get_connection
    return self.create_connection()
           ^^^^^^^^^^^^^^^^^^^^^^^^
  File "/home/frappe/frappe-bench/apps/frappe/frappe/database/mariadb/database.py", line 117, in create_connection
    return pymysql.connect(**self.get_connection_settings())
           ^^^^^^^^^^^^^^^^^^^^^^^^^^^^^^^^^^^^^^^^^^^^^^^^^
  File "/home/frappe/frappe-bench/env/lib/python3.11/site-packages/pymysql/connections.py", line 361, in __init__
    self.connect()
  File "/home/frappe/frappe-bench/env/lib/python3.11/site-packages/pymysql/connections.py", line 669, in connect
    self._request_authentication()
  File "/home/frappe/frappe-bench/env/lib/python3.11/site-packages/pymysql/connections.py", line 957, in _request_authentication
    auth_packet = self._read_packet()
                  ^^^^^^^^^^^^^^^^^^^
  File "/home/frappe/frappe-bench/env/lib/python3.11/site-packages/pymysql/connections.py", line 775, in _read_packet
    packet.raise_for_error()
  File "/home/frappe/frappe-bench/env/lib/python3.11/site-packages/pymysql/protocol.py", line 219, in raise_for_error
    err.raise_mysql_exception(self._data)
  File "/home/frappe/frappe-bench/env/lib/python3.11/site-packages/pymysql/err.py", line 150, in raise_mysql_exception
    raise errorclass(errno, errval)
pymysql.err.OperationalError: (1045, "Access denied for user '_e1ef3e0c4bdfa786'@'172.18.0.4' (using password: YES)")
2025-06-23 06:53:48,079 ERROR scheduler Exception in Enqueue Events for Site site1.localhost
Traceback (most recent call last):
  File "/home/frappe/frappe-bench/apps/frappe/frappe/utils/scheduler.py", line 99, in enqueue_events_for_site
    if is_scheduler_inactive():
       ^^^^^^^^^^^^^^^^^^^^^^^
  File "/home/frappe/frappe-bench/apps/frappe/frappe/utils/scheduler.py", line 143, in is_scheduler_inactive
    if is_scheduler_disabled(verbose=verbose):
       ^^^^^^^^^^^^^^^^^^^^^^^^^^^^^^^^^^^^^^
  File "/home/frappe/frappe-bench/apps/frappe/frappe/utils/scheduler.py", line 156, in is_scheduler_disabled
    frappe.db.get_single_value("System Settings", "enable_scheduler")
  File "/home/frappe/frappe-bench/apps/frappe/frappe/database/database.py", line 837, in get_single_value
    ).run()
      ^^^^^
  File "/home/frappe/frappe-bench/apps/frappe/frappe/query_builder/utils.py", line 87, in execute_query
    result = frappe.db.sql(query, params, *args, **kwargs)  # nosemgrep
             ^^^^^^^^^^^^^^^^^^^^^^^^^^^^^^^^^^^^^^^^^^^^^
  File "/home/frappe/frappe-bench/apps/frappe/frappe/database/database.py", line 207, in sql
    self.connect()
  File "/home/frappe/frappe-bench/apps/frappe/frappe/database/database.py", line 112, in connect
    self._conn: "MariadbConnection" | "PostgresConnection" = self.get_connection()
                                                             ^^^^^^^^^^^^^^^^^^^^^
  File "/home/frappe/frappe-bench/apps/frappe/frappe/database/mariadb/database.py", line 108, in get_connection
    conn = self._get_connection()
           ^^^^^^^^^^^^^^^^^^^^^^
  File "/home/frappe/frappe-bench/apps/frappe/frappe/database/mariadb/database.py", line 114, in _get_connection
    return self.create_connection()
           ^^^^^^^^^^^^^^^^^^^^^^^^
  File "/home/frappe/frappe-bench/apps/frappe/frappe/database/mariadb/database.py", line 117, in create_connection
    return pymysql.connect(**self.get_connection_settings())
           ^^^^^^^^^^^^^^^^^^^^^^^^^^^^^^^^^^^^^^^^^^^^^^^^^
  File "/home/frappe/frappe-bench/env/lib/python3.11/site-packages/pymysql/connections.py", line 361, in __init__
    self.connect()
  File "/home/frappe/frappe-bench/env/lib/python3.11/site-packages/pymysql/connections.py", line 669, in connect
    self._request_authentication()
  File "/home/frappe/frappe-bench/env/lib/python3.11/site-packages/pymysql/connections.py", line 957, in _request_authentication
    auth_packet = self._read_packet()
                  ^^^^^^^^^^^^^^^^^^^
  File "/home/frappe/frappe-bench/env/lib/python3.11/site-packages/pymysql/connections.py", line 775, in _read_packet
    packet.raise_for_error()
  File "/home/frappe/frappe-bench/env/lib/python3.11/site-packages/pymysql/protocol.py", line 219, in raise_for_error
    err.raise_mysql_exception(self._data)
  File "/home/frappe/frappe-bench/env/lib/python3.11/site-packages/pymysql/err.py", line 150, in raise_mysql_exception
    raise errorclass(errno, errval)
pymysql.err.OperationalError: (1045, "Access denied for user '_e1ef3e0c4bdfa786'@'172.18.0.4' (using password: YES)")
2025-06-23 06:54:50,231 ERROR scheduler Exception in Enqueue Events for Site site1.localhost
Traceback (most recent call last):
  File "/home/frappe/frappe-bench/apps/frappe/frappe/utils/scheduler.py", line 99, in enqueue_events_for_site
    if is_scheduler_inactive():
       ^^^^^^^^^^^^^^^^^^^^^^^
  File "/home/frappe/frappe-bench/apps/frappe/frappe/utils/scheduler.py", line 143, in is_scheduler_inactive
    if is_scheduler_disabled(verbose=verbose):
       ^^^^^^^^^^^^^^^^^^^^^^^^^^^^^^^^^^^^^^
  File "/home/frappe/frappe-bench/apps/frappe/frappe/utils/scheduler.py", line 156, in is_scheduler_disabled
    frappe.db.get_single_value("System Settings", "enable_scheduler")
  File "/home/frappe/frappe-bench/apps/frappe/frappe/database/database.py", line 837, in get_single_value
    ).run()
      ^^^^^
  File "/home/frappe/frappe-bench/apps/frappe/frappe/query_builder/utils.py", line 87, in execute_query
    result = frappe.db.sql(query, params, *args, **kwargs)  # nosemgrep
             ^^^^^^^^^^^^^^^^^^^^^^^^^^^^^^^^^^^^^^^^^^^^^
  File "/home/frappe/frappe-bench/apps/frappe/frappe/database/database.py", line 207, in sql
    self.connect()
  File "/home/frappe/frappe-bench/apps/frappe/frappe/database/database.py", line 112, in connect
    self._conn: "MariadbConnection" | "PostgresConnection" = self.get_connection()
                                                             ^^^^^^^^^^^^^^^^^^^^^
  File "/home/frappe/frappe-bench/apps/frappe/frappe/database/mariadb/database.py", line 108, in get_connection
    conn = self._get_connection()
           ^^^^^^^^^^^^^^^^^^^^^^
  File "/home/frappe/frappe-bench/apps/frappe/frappe/database/mariadb/database.py", line 114, in _get_connection
    return self.create_connection()
           ^^^^^^^^^^^^^^^^^^^^^^^^
  File "/home/frappe/frappe-bench/apps/frappe/frappe/database/mariadb/database.py", line 117, in create_connection
    return pymysql.connect(**self.get_connection_settings())
           ^^^^^^^^^^^^^^^^^^^^^^^^^^^^^^^^^^^^^^^^^^^^^^^^^
  File "/home/frappe/frappe-bench/env/lib/python3.11/site-packages/pymysql/connections.py", line 361, in __init__
    self.connect()
  File "/home/frappe/frappe-bench/env/lib/python3.11/site-packages/pymysql/connections.py", line 669, in connect
    self._request_authentication()
  File "/home/frappe/frappe-bench/env/lib/python3.11/site-packages/pymysql/connections.py", line 957, in _request_authentication
    auth_packet = self._read_packet()
                  ^^^^^^^^^^^^^^^^^^^
  File "/home/frappe/frappe-bench/env/lib/python3.11/site-packages/pymysql/connections.py", line 775, in _read_packet
    packet.raise_for_error()
  File "/home/frappe/frappe-bench/env/lib/python3.11/site-packages/pymysql/protocol.py", line 219, in raise_for_error
    err.raise_mysql_exception(self._data)
  File "/home/frappe/frappe-bench/env/lib/python3.11/site-packages/pymysql/err.py", line 150, in raise_mysql_exception
    raise errorclass(errno, errval)
pymysql.err.OperationalError: (1045, "Access denied for user '_e1ef3e0c4bdfa786'@'172.18.0.4' (using password: YES)")
2025-06-23 06:55:51,123 ERROR scheduler Exception in Enqueue Events for Site site1.localhost
Traceback (most recent call last):
  File "/home/frappe/frappe-bench/apps/frappe/frappe/utils/scheduler.py", line 99, in enqueue_events_for_site
    if is_scheduler_inactive():
       ^^^^^^^^^^^^^^^^^^^^^^^
  File "/home/frappe/frappe-bench/apps/frappe/frappe/utils/scheduler.py", line 143, in is_scheduler_inactive
    if is_scheduler_disabled(verbose=verbose):
       ^^^^^^^^^^^^^^^^^^^^^^^^^^^^^^^^^^^^^^
  File "/home/frappe/frappe-bench/apps/frappe/frappe/utils/scheduler.py", line 156, in is_scheduler_disabled
    frappe.db.get_single_value("System Settings", "enable_scheduler")
  File "/home/frappe/frappe-bench/apps/frappe/frappe/database/database.py", line 837, in get_single_value
    ).run()
      ^^^^^
  File "/home/frappe/frappe-bench/apps/frappe/frappe/query_builder/utils.py", line 87, in execute_query
    result = frappe.db.sql(query, params, *args, **kwargs)  # nosemgrep
             ^^^^^^^^^^^^^^^^^^^^^^^^^^^^^^^^^^^^^^^^^^^^^
  File "/home/frappe/frappe-bench/apps/frappe/frappe/database/database.py", line 207, in sql
    self.connect()
  File "/home/frappe/frappe-bench/apps/frappe/frappe/database/database.py", line 112, in connect
    self._conn: "MariadbConnection" | "PostgresConnection" = self.get_connection()
                                                             ^^^^^^^^^^^^^^^^^^^^^
  File "/home/frappe/frappe-bench/apps/frappe/frappe/database/mariadb/database.py", line 108, in get_connection
    conn = self._get_connection()
           ^^^^^^^^^^^^^^^^^^^^^^
  File "/home/frappe/frappe-bench/apps/frappe/frappe/database/mariadb/database.py", line 114, in _get_connection
    return self.create_connection()
           ^^^^^^^^^^^^^^^^^^^^^^^^
  File "/home/frappe/frappe-bench/apps/frappe/frappe/database/mariadb/database.py", line 117, in create_connection
    return pymysql.connect(**self.get_connection_settings())
           ^^^^^^^^^^^^^^^^^^^^^^^^^^^^^^^^^^^^^^^^^^^^^^^^^
  File "/home/frappe/frappe-bench/env/lib/python3.11/site-packages/pymysql/connections.py", line 361, in __init__
    self.connect()
  File "/home/frappe/frappe-bench/env/lib/python3.11/site-packages/pymysql/connections.py", line 669, in connect
    self._request_authentication()
  File "/home/frappe/frappe-bench/env/lib/python3.11/site-packages/pymysql/connections.py", line 957, in _request_authentication
    auth_packet = self._read_packet()
                  ^^^^^^^^^^^^^^^^^^^
  File "/home/frappe/frappe-bench/env/lib/python3.11/site-packages/pymysql/connections.py", line 775, in _read_packet
    packet.raise_for_error()
  File "/home/frappe/frappe-bench/env/lib/python3.11/site-packages/pymysql/protocol.py", line 219, in raise_for_error
    err.raise_mysql_exception(self._data)
  File "/home/frappe/frappe-bench/env/lib/python3.11/site-packages/pymysql/err.py", line 150, in raise_mysql_exception
    raise errorclass(errno, errval)
pymysql.err.OperationalError: (1045, "Access denied for user '_e1ef3e0c4bdfa786'@'172.18.0.4' (using password: YES)")
2025-06-23 06:56:52,132 ERROR scheduler Exception in Enqueue Events for Site site1.localhost
Traceback (most recent call last):
  File "/home/frappe/frappe-bench/apps/frappe/frappe/utils/scheduler.py", line 99, in enqueue_events_for_site
    if is_scheduler_inactive():
       ^^^^^^^^^^^^^^^^^^^^^^^
  File "/home/frappe/frappe-bench/apps/frappe/frappe/utils/scheduler.py", line 143, in is_scheduler_inactive
    if is_scheduler_disabled(verbose=verbose):
       ^^^^^^^^^^^^^^^^^^^^^^^^^^^^^^^^^^^^^^
  File "/home/frappe/frappe-bench/apps/frappe/frappe/utils/scheduler.py", line 156, in is_scheduler_disabled
    frappe.db.get_single_value("System Settings", "enable_scheduler")
  File "/home/frappe/frappe-bench/apps/frappe/frappe/database/database.py", line 837, in get_single_value
    ).run()
      ^^^^^
  File "/home/frappe/frappe-bench/apps/frappe/frappe/query_builder/utils.py", line 87, in execute_query
    result = frappe.db.sql(query, params, *args, **kwargs)  # nosemgrep
             ^^^^^^^^^^^^^^^^^^^^^^^^^^^^^^^^^^^^^^^^^^^^^
  File "/home/frappe/frappe-bench/apps/frappe/frappe/database/database.py", line 207, in sql
    self.connect()
  File "/home/frappe/frappe-bench/apps/frappe/frappe/database/database.py", line 112, in connect
    self._conn: "MariadbConnection" | "PostgresConnection" = self.get_connection()
                                                             ^^^^^^^^^^^^^^^^^^^^^
  File "/home/frappe/frappe-bench/apps/frappe/frappe/database/mariadb/database.py", line 108, in get_connection
    conn = self._get_connection()
           ^^^^^^^^^^^^^^^^^^^^^^
  File "/home/frappe/frappe-bench/apps/frappe/frappe/database/mariadb/database.py", line 114, in _get_connection
    return self.create_connection()
           ^^^^^^^^^^^^^^^^^^^^^^^^
  File "/home/frappe/frappe-bench/apps/frappe/frappe/database/mariadb/database.py", line 117, in create_connection
    return pymysql.connect(**self.get_connection_settings())
           ^^^^^^^^^^^^^^^^^^^^^^^^^^^^^^^^^^^^^^^^^^^^^^^^^
  File "/home/frappe/frappe-bench/env/lib/python3.11/site-packages/pymysql/connections.py", line 361, in __init__
    self.connect()
  File "/home/frappe/frappe-bench/env/lib/python3.11/site-packages/pymysql/connections.py", line 669, in connect
    self._request_authentication()
  File "/home/frappe/frappe-bench/env/lib/python3.11/site-packages/pymysql/connections.py", line 957, in _request_authentication
    auth_packet = self._read_packet()
                  ^^^^^^^^^^^^^^^^^^^
  File "/home/frappe/frappe-bench/env/lib/python3.11/site-packages/pymysql/connections.py", line 775, in _read_packet
    packet.raise_for_error()
  File "/home/frappe/frappe-bench/env/lib/python3.11/site-packages/pymysql/protocol.py", line 219, in raise_for_error
    err.raise_mysql_exception(self._data)
  File "/home/frappe/frappe-bench/env/lib/python3.11/site-packages/pymysql/err.py", line 150, in raise_mysql_exception
    raise errorclass(errno, errval)
pymysql.err.OperationalError: (1045, "Access denied for user '_e1ef3e0c4bdfa786'@'172.18.0.4' (using password: YES)")
2025-06-23 06:57:53,729 ERROR scheduler Exception in Enqueue Events for Site site1.localhost
Traceback (most recent call last):
  File "/home/frappe/frappe-bench/apps/frappe/frappe/utils/scheduler.py", line 99, in enqueue_events_for_site
    if is_scheduler_inactive():
       ^^^^^^^^^^^^^^^^^^^^^^^
  File "/home/frappe/frappe-bench/apps/frappe/frappe/utils/scheduler.py", line 143, in is_scheduler_inactive
    if is_scheduler_disabled(verbose=verbose):
       ^^^^^^^^^^^^^^^^^^^^^^^^^^^^^^^^^^^^^^
  File "/home/frappe/frappe-bench/apps/frappe/frappe/utils/scheduler.py", line 156, in is_scheduler_disabled
    frappe.db.get_single_value("System Settings", "enable_scheduler")
  File "/home/frappe/frappe-bench/apps/frappe/frappe/database/database.py", line 837, in get_single_value
    ).run()
      ^^^^^
  File "/home/frappe/frappe-bench/apps/frappe/frappe/query_builder/utils.py", line 87, in execute_query
    result = frappe.db.sql(query, params, *args, **kwargs)  # nosemgrep
             ^^^^^^^^^^^^^^^^^^^^^^^^^^^^^^^^^^^^^^^^^^^^^
  File "/home/frappe/frappe-bench/apps/frappe/frappe/database/database.py", line 207, in sql
    self.connect()
  File "/home/frappe/frappe-bench/apps/frappe/frappe/database/database.py", line 112, in connect
    self._conn: "MariadbConnection" | "PostgresConnection" = self.get_connection()
                                                             ^^^^^^^^^^^^^^^^^^^^^
  File "/home/frappe/frappe-bench/apps/frappe/frappe/database/mariadb/database.py", line 108, in get_connection
    conn = self._get_connection()
           ^^^^^^^^^^^^^^^^^^^^^^
  File "/home/frappe/frappe-bench/apps/frappe/frappe/database/mariadb/database.py", line 114, in _get_connection
    return self.create_connection()
           ^^^^^^^^^^^^^^^^^^^^^^^^
  File "/home/frappe/frappe-bench/apps/frappe/frappe/database/mariadb/database.py", line 117, in create_connection
    return pymysql.connect(**self.get_connection_settings())
           ^^^^^^^^^^^^^^^^^^^^^^^^^^^^^^^^^^^^^^^^^^^^^^^^^
  File "/home/frappe/frappe-bench/env/lib/python3.11/site-packages/pymysql/connections.py", line 361, in __init__
    self.connect()
  File "/home/frappe/frappe-bench/env/lib/python3.11/site-packages/pymysql/connections.py", line 669, in connect
    self._request_authentication()
  File "/home/frappe/frappe-bench/env/lib/python3.11/site-packages/pymysql/connections.py", line 957, in _request_authentication
    auth_packet = self._read_packet()
                  ^^^^^^^^^^^^^^^^^^^
  File "/home/frappe/frappe-bench/env/lib/python3.11/site-packages/pymysql/connections.py", line 775, in _read_packet
    packet.raise_for_error()
  File "/home/frappe/frappe-bench/env/lib/python3.11/site-packages/pymysql/protocol.py", line 219, in raise_for_error
    err.raise_mysql_exception(self._data)
  File "/home/frappe/frappe-bench/env/lib/python3.11/site-packages/pymysql/err.py", line 150, in raise_mysql_exception
    raise errorclass(errno, errval)
pymysql.err.OperationalError: (1045, "Access denied for user '_e1ef3e0c4bdfa786'@'172.18.0.4' (using password: YES)")
2025-06-23 06:58:55,311 ERROR scheduler Exception in Enqueue Events for Site site1.localhost
Traceback (most recent call last):
  File "/home/frappe/frappe-bench/apps/frappe/frappe/utils/scheduler.py", line 99, in enqueue_events_for_site
    if is_scheduler_inactive():
       ^^^^^^^^^^^^^^^^^^^^^^^
  File "/home/frappe/frappe-bench/apps/frappe/frappe/utils/scheduler.py", line 143, in is_scheduler_inactive
    if is_scheduler_disabled(verbose=verbose):
       ^^^^^^^^^^^^^^^^^^^^^^^^^^^^^^^^^^^^^^
  File "/home/frappe/frappe-bench/apps/frappe/frappe/utils/scheduler.py", line 156, in is_scheduler_disabled
    frappe.db.get_single_value("System Settings", "enable_scheduler")
  File "/home/frappe/frappe-bench/apps/frappe/frappe/database/database.py", line 837, in get_single_value
    ).run()
      ^^^^^
  File "/home/frappe/frappe-bench/apps/frappe/frappe/query_builder/utils.py", line 87, in execute_query
    result = frappe.db.sql(query, params, *args, **kwargs)  # nosemgrep
             ^^^^^^^^^^^^^^^^^^^^^^^^^^^^^^^^^^^^^^^^^^^^^
  File "/home/frappe/frappe-bench/apps/frappe/frappe/database/database.py", line 207, in sql
    self.connect()
  File "/home/frappe/frappe-bench/apps/frappe/frappe/database/database.py", line 112, in connect
    self._conn: "MariadbConnection" | "PostgresConnection" = self.get_connection()
                                                             ^^^^^^^^^^^^^^^^^^^^^
  File "/home/frappe/frappe-bench/apps/frappe/frappe/database/mariadb/database.py", line 108, in get_connection
    conn = self._get_connection()
           ^^^^^^^^^^^^^^^^^^^^^^
  File "/home/frappe/frappe-bench/apps/frappe/frappe/database/mariadb/database.py", line 114, in _get_connection
    return self.create_connection()
           ^^^^^^^^^^^^^^^^^^^^^^^^
  File "/home/frappe/frappe-bench/apps/frappe/frappe/database/mariadb/database.py", line 117, in create_connection
    return pymysql.connect(**self.get_connection_settings())
           ^^^^^^^^^^^^^^^^^^^^^^^^^^^^^^^^^^^^^^^^^^^^^^^^^
  File "/home/frappe/frappe-bench/env/lib/python3.11/site-packages/pymysql/connections.py", line 361, in __init__
    self.connect()
  File "/home/frappe/frappe-bench/env/lib/python3.11/site-packages/pymysql/connections.py", line 669, in connect
    self._request_authentication()
  File "/home/frappe/frappe-bench/env/lib/python3.11/site-packages/pymysql/connections.py", line 957, in _request_authentication
    auth_packet = self._read_packet()
                  ^^^^^^^^^^^^^^^^^^^
  File "/home/frappe/frappe-bench/env/lib/python3.11/site-packages/pymysql/connections.py", line 775, in _read_packet
    packet.raise_for_error()
  File "/home/frappe/frappe-bench/env/lib/python3.11/site-packages/pymysql/protocol.py", line 219, in raise_for_error
    err.raise_mysql_exception(self._data)
  File "/home/frappe/frappe-bench/env/lib/python3.11/site-packages/pymysql/err.py", line 150, in raise_mysql_exception
    raise errorclass(errno, errval)
pymysql.err.OperationalError: (1045, "Access denied for user '_e1ef3e0c4bdfa786'@'172.18.0.4' (using password: YES)")
2025-06-23 06:59:56,883 ERROR scheduler Exception in Enqueue Events for Site site1.localhost
Traceback (most recent call last):
  File "/home/frappe/frappe-bench/apps/frappe/frappe/utils/scheduler.py", line 99, in enqueue_events_for_site
    if is_scheduler_inactive():
       ^^^^^^^^^^^^^^^^^^^^^^^
  File "/home/frappe/frappe-bench/apps/frappe/frappe/utils/scheduler.py", line 143, in is_scheduler_inactive
    if is_scheduler_disabled(verbose=verbose):
       ^^^^^^^^^^^^^^^^^^^^^^^^^^^^^^^^^^^^^^
  File "/home/frappe/frappe-bench/apps/frappe/frappe/utils/scheduler.py", line 156, in is_scheduler_disabled
    frappe.db.get_single_value("System Settings", "enable_scheduler")
  File "/home/frappe/frappe-bench/apps/frappe/frappe/database/database.py", line 837, in get_single_value
    ).run()
      ^^^^^
  File "/home/frappe/frappe-bench/apps/frappe/frappe/query_builder/utils.py", line 87, in execute_query
    result = frappe.db.sql(query, params, *args, **kwargs)  # nosemgrep
             ^^^^^^^^^^^^^^^^^^^^^^^^^^^^^^^^^^^^^^^^^^^^^
  File "/home/frappe/frappe-bench/apps/frappe/frappe/database/database.py", line 207, in sql
    self.connect()
  File "/home/frappe/frappe-bench/apps/frappe/frappe/database/database.py", line 112, in connect
    self._conn: "MariadbConnection" | "PostgresConnection" = self.get_connection()
                                                             ^^^^^^^^^^^^^^^^^^^^^
  File "/home/frappe/frappe-bench/apps/frappe/frappe/database/mariadb/database.py", line 108, in get_connection
    conn = self._get_connection()
           ^^^^^^^^^^^^^^^^^^^^^^
  File "/home/frappe/frappe-bench/apps/frappe/frappe/database/mariadb/database.py", line 114, in _get_connection
    return self.create_connection()
           ^^^^^^^^^^^^^^^^^^^^^^^^
  File "/home/frappe/frappe-bench/apps/frappe/frappe/database/mariadb/database.py", line 117, in create_connection
    return pymysql.connect(**self.get_connection_settings())
           ^^^^^^^^^^^^^^^^^^^^^^^^^^^^^^^^^^^^^^^^^^^^^^^^^
  File "/home/frappe/frappe-bench/env/lib/python3.11/site-packages/pymysql/connections.py", line 361, in __init__
    self.connect()
  File "/home/frappe/frappe-bench/env/lib/python3.11/site-packages/pymysql/connections.py", line 669, in connect
    self._request_authentication()
  File "/home/frappe/frappe-bench/env/lib/python3.11/site-packages/pymysql/connections.py", line 957, in _request_authentication
    auth_packet = self._read_packet()
                  ^^^^^^^^^^^^^^^^^^^
  File "/home/frappe/frappe-bench/env/lib/python3.11/site-packages/pymysql/connections.py", line 775, in _read_packet
    packet.raise_for_error()
  File "/home/frappe/frappe-bench/env/lib/python3.11/site-packages/pymysql/protocol.py", line 219, in raise_for_error
    err.raise_mysql_exception(self._data)
  File "/home/frappe/frappe-bench/env/lib/python3.11/site-packages/pymysql/err.py", line 150, in raise_mysql_exception
    raise errorclass(errno, errval)
pymysql.err.OperationalError: (1045, "Access denied for user '_e1ef3e0c4bdfa786'@'172.18.0.4' (using password: YES)")
2025-06-23 07:00:59,061 ERROR scheduler Exception in Enqueue Events for Site site1.localhost
Traceback (most recent call last):
  File "/home/frappe/frappe-bench/apps/frappe/frappe/utils/scheduler.py", line 99, in enqueue_events_for_site
    if is_scheduler_inactive():
       ^^^^^^^^^^^^^^^^^^^^^^^
  File "/home/frappe/frappe-bench/apps/frappe/frappe/utils/scheduler.py", line 143, in is_scheduler_inactive
    if is_scheduler_disabled(verbose=verbose):
       ^^^^^^^^^^^^^^^^^^^^^^^^^^^^^^^^^^^^^^
  File "/home/frappe/frappe-bench/apps/frappe/frappe/utils/scheduler.py", line 156, in is_scheduler_disabled
    frappe.db.get_single_value("System Settings", "enable_scheduler")
  File "/home/frappe/frappe-bench/apps/frappe/frappe/database/database.py", line 837, in get_single_value
    ).run()
      ^^^^^
  File "/home/frappe/frappe-bench/apps/frappe/frappe/query_builder/utils.py", line 87, in execute_query
    result = frappe.db.sql(query, params, *args, **kwargs)  # nosemgrep
             ^^^^^^^^^^^^^^^^^^^^^^^^^^^^^^^^^^^^^^^^^^^^^
  File "/home/frappe/frappe-bench/apps/frappe/frappe/database/database.py", line 207, in sql
    self.connect()
  File "/home/frappe/frappe-bench/apps/frappe/frappe/database/database.py", line 112, in connect
    self._conn: "MariadbConnection" | "PostgresConnection" = self.get_connection()
                                                             ^^^^^^^^^^^^^^^^^^^^^
  File "/home/frappe/frappe-bench/apps/frappe/frappe/database/mariadb/database.py", line 108, in get_connection
    conn = self._get_connection()
           ^^^^^^^^^^^^^^^^^^^^^^
  File "/home/frappe/frappe-bench/apps/frappe/frappe/database/mariadb/database.py", line 114, in _get_connection
    return self.create_connection()
           ^^^^^^^^^^^^^^^^^^^^^^^^
  File "/home/frappe/frappe-bench/apps/frappe/frappe/database/mariadb/database.py", line 117, in create_connection
    return pymysql.connect(**self.get_connection_settings())
           ^^^^^^^^^^^^^^^^^^^^^^^^^^^^^^^^^^^^^^^^^^^^^^^^^
  File "/home/frappe/frappe-bench/env/lib/python3.11/site-packages/pymysql/connections.py", line 361, in __init__
    self.connect()
  File "/home/frappe/frappe-bench/env/lib/python3.11/site-packages/pymysql/connections.py", line 669, in connect
    self._request_authentication()
  File "/home/frappe/frappe-bench/env/lib/python3.11/site-packages/pymysql/connections.py", line 957, in _request_authentication
    auth_packet = self._read_packet()
                  ^^^^^^^^^^^^^^^^^^^
  File "/home/frappe/frappe-bench/env/lib/python3.11/site-packages/pymysql/connections.py", line 775, in _read_packet
    packet.raise_for_error()
  File "/home/frappe/frappe-bench/env/lib/python3.11/site-packages/pymysql/protocol.py", line 219, in raise_for_error
    err.raise_mysql_exception(self._data)
  File "/home/frappe/frappe-bench/env/lib/python3.11/site-packages/pymysql/err.py", line 150, in raise_mysql_exception
    raise errorclass(errno, errval)
pymysql.err.OperationalError: (1045, "Access denied for user '_e1ef3e0c4bdfa786'@'172.18.0.4' (using password: YES)")
2025-06-23 07:02:01,069 ERROR scheduler Exception in Enqueue Events for Site site1.localhost
Traceback (most recent call last):
  File "/home/frappe/frappe-bench/apps/frappe/frappe/utils/scheduler.py", line 99, in enqueue_events_for_site
    if is_scheduler_inactive():
       ^^^^^^^^^^^^^^^^^^^^^^^
  File "/home/frappe/frappe-bench/apps/frappe/frappe/utils/scheduler.py", line 143, in is_scheduler_inactive
    if is_scheduler_disabled(verbose=verbose):
       ^^^^^^^^^^^^^^^^^^^^^^^^^^^^^^^^^^^^^^
  File "/home/frappe/frappe-bench/apps/frappe/frappe/utils/scheduler.py", line 156, in is_scheduler_disabled
    frappe.db.get_single_value("System Settings", "enable_scheduler")
  File "/home/frappe/frappe-bench/apps/frappe/frappe/database/database.py", line 837, in get_single_value
    ).run()
      ^^^^^
  File "/home/frappe/frappe-bench/apps/frappe/frappe/query_builder/utils.py", line 87, in execute_query
    result = frappe.db.sql(query, params, *args, **kwargs)  # nosemgrep
             ^^^^^^^^^^^^^^^^^^^^^^^^^^^^^^^^^^^^^^^^^^^^^
  File "/home/frappe/frappe-bench/apps/frappe/frappe/database/database.py", line 207, in sql
    self.connect()
  File "/home/frappe/frappe-bench/apps/frappe/frappe/database/database.py", line 112, in connect
    self._conn: "MariadbConnection" | "PostgresConnection" = self.get_connection()
                                                             ^^^^^^^^^^^^^^^^^^^^^
  File "/home/frappe/frappe-bench/apps/frappe/frappe/database/mariadb/database.py", line 108, in get_connection
    conn = self._get_connection()
           ^^^^^^^^^^^^^^^^^^^^^^
  File "/home/frappe/frappe-bench/apps/frappe/frappe/database/mariadb/database.py", line 114, in _get_connection
    return self.create_connection()
           ^^^^^^^^^^^^^^^^^^^^^^^^
  File "/home/frappe/frappe-bench/apps/frappe/frappe/database/mariadb/database.py", line 117, in create_connection
    return pymysql.connect(**self.get_connection_settings())
           ^^^^^^^^^^^^^^^^^^^^^^^^^^^^^^^^^^^^^^^^^^^^^^^^^
  File "/home/frappe/frappe-bench/env/lib/python3.11/site-packages/pymysql/connections.py", line 361, in __init__
    self.connect()
  File "/home/frappe/frappe-bench/env/lib/python3.11/site-packages/pymysql/connections.py", line 669, in connect
    self._request_authentication()
  File "/home/frappe/frappe-bench/env/lib/python3.11/site-packages/pymysql/connections.py", line 957, in _request_authentication
    auth_packet = self._read_packet()
                  ^^^^^^^^^^^^^^^^^^^
  File "/home/frappe/frappe-bench/env/lib/python3.11/site-packages/pymysql/connections.py", line 775, in _read_packet
    packet.raise_for_error()
  File "/home/frappe/frappe-bench/env/lib/python3.11/site-packages/pymysql/protocol.py", line 219, in raise_for_error
    err.raise_mysql_exception(self._data)
  File "/home/frappe/frappe-bench/env/lib/python3.11/site-packages/pymysql/err.py", line 150, in raise_mysql_exception
    raise errorclass(errno, errval)
pymysql.err.OperationalError: (1045, "Access denied for user '_e1ef3e0c4bdfa786'@'172.18.0.4' (using password: YES)")
2025-06-23 07:03:02,297 ERROR scheduler Exception in Enqueue Events for Site site1.localhost
Traceback (most recent call last):
  File "/home/frappe/frappe-bench/apps/frappe/frappe/utils/scheduler.py", line 99, in enqueue_events_for_site
    if is_scheduler_inactive():
       ^^^^^^^^^^^^^^^^^^^^^^^
  File "/home/frappe/frappe-bench/apps/frappe/frappe/utils/scheduler.py", line 143, in is_scheduler_inactive
    if is_scheduler_disabled(verbose=verbose):
       ^^^^^^^^^^^^^^^^^^^^^^^^^^^^^^^^^^^^^^
  File "/home/frappe/frappe-bench/apps/frappe/frappe/utils/scheduler.py", line 156, in is_scheduler_disabled
    frappe.db.get_single_value("System Settings", "enable_scheduler")
  File "/home/frappe/frappe-bench/apps/frappe/frappe/database/database.py", line 837, in get_single_value
    ).run()
      ^^^^^
  File "/home/frappe/frappe-bench/apps/frappe/frappe/query_builder/utils.py", line 87, in execute_query
    result = frappe.db.sql(query, params, *args, **kwargs)  # nosemgrep
             ^^^^^^^^^^^^^^^^^^^^^^^^^^^^^^^^^^^^^^^^^^^^^
  File "/home/frappe/frappe-bench/apps/frappe/frappe/database/database.py", line 207, in sql
    self.connect()
  File "/home/frappe/frappe-bench/apps/frappe/frappe/database/database.py", line 112, in connect
    self._conn: "MariadbConnection" | "PostgresConnection" = self.get_connection()
                                                             ^^^^^^^^^^^^^^^^^^^^^
  File "/home/frappe/frappe-bench/apps/frappe/frappe/database/mariadb/database.py", line 108, in get_connection
    conn = self._get_connection()
           ^^^^^^^^^^^^^^^^^^^^^^
  File "/home/frappe/frappe-bench/apps/frappe/frappe/database/mariadb/database.py", line 114, in _get_connection
    return self.create_connection()
           ^^^^^^^^^^^^^^^^^^^^^^^^
  File "/home/frappe/frappe-bench/apps/frappe/frappe/database/mariadb/database.py", line 117, in create_connection
    return pymysql.connect(**self.get_connection_settings())
           ^^^^^^^^^^^^^^^^^^^^^^^^^^^^^^^^^^^^^^^^^^^^^^^^^
  File "/home/frappe/frappe-bench/env/lib/python3.11/site-packages/pymysql/connections.py", line 361, in __init__
    self.connect()
  File "/home/frappe/frappe-bench/env/lib/python3.11/site-packages/pymysql/connections.py", line 669, in connect
    self._request_authentication()
  File "/home/frappe/frappe-bench/env/lib/python3.11/site-packages/pymysql/connections.py", line 957, in _request_authentication
    auth_packet = self._read_packet()
                  ^^^^^^^^^^^^^^^^^^^
  File "/home/frappe/frappe-bench/env/lib/python3.11/site-packages/pymysql/connections.py", line 775, in _read_packet
    packet.raise_for_error()
  File "/home/frappe/frappe-bench/env/lib/python3.11/site-packages/pymysql/protocol.py", line 219, in raise_for_error
    err.raise_mysql_exception(self._data)
  File "/home/frappe/frappe-bench/env/lib/python3.11/site-packages/pymysql/err.py", line 150, in raise_mysql_exception
    raise errorclass(errno, errval)
pymysql.err.OperationalError: (1045, "Access denied for user '_e1ef3e0c4bdfa786'@'172.18.0.4' (using password: YES)")
2025-06-23 07:04:03,272 ERROR scheduler Exception in Enqueue Events for Site site1.localhost
Traceback (most recent call last):
  File "/home/frappe/frappe-bench/apps/frappe/frappe/utils/scheduler.py", line 99, in enqueue_events_for_site
    if is_scheduler_inactive():
       ^^^^^^^^^^^^^^^^^^^^^^^
  File "/home/frappe/frappe-bench/apps/frappe/frappe/utils/scheduler.py", line 143, in is_scheduler_inactive
    if is_scheduler_disabled(verbose=verbose):
       ^^^^^^^^^^^^^^^^^^^^^^^^^^^^^^^^^^^^^^
  File "/home/frappe/frappe-bench/apps/frappe/frappe/utils/scheduler.py", line 156, in is_scheduler_disabled
    frappe.db.get_single_value("System Settings", "enable_scheduler")
  File "/home/frappe/frappe-bench/apps/frappe/frappe/database/database.py", line 837, in get_single_value
    ).run()
      ^^^^^
  File "/home/frappe/frappe-bench/apps/frappe/frappe/query_builder/utils.py", line 87, in execute_query
    result = frappe.db.sql(query, params, *args, **kwargs)  # nosemgrep
             ^^^^^^^^^^^^^^^^^^^^^^^^^^^^^^^^^^^^^^^^^^^^^
  File "/home/frappe/frappe-bench/apps/frappe/frappe/database/database.py", line 207, in sql
    self.connect()
  File "/home/frappe/frappe-bench/apps/frappe/frappe/database/database.py", line 112, in connect
    self._conn: "MariadbConnection" | "PostgresConnection" = self.get_connection()
                                                             ^^^^^^^^^^^^^^^^^^^^^
  File "/home/frappe/frappe-bench/apps/frappe/frappe/database/mariadb/database.py", line 108, in get_connection
    conn = self._get_connection()
           ^^^^^^^^^^^^^^^^^^^^^^
  File "/home/frappe/frappe-bench/apps/frappe/frappe/database/mariadb/database.py", line 114, in _get_connection
    return self.create_connection()
           ^^^^^^^^^^^^^^^^^^^^^^^^
  File "/home/frappe/frappe-bench/apps/frappe/frappe/database/mariadb/database.py", line 117, in create_connection
    return pymysql.connect(**self.get_connection_settings())
           ^^^^^^^^^^^^^^^^^^^^^^^^^^^^^^^^^^^^^^^^^^^^^^^^^
  File "/home/frappe/frappe-bench/env/lib/python3.11/site-packages/pymysql/connections.py", line 361, in __init__
    self.connect()
  File "/home/frappe/frappe-bench/env/lib/python3.11/site-packages/pymysql/connections.py", line 669, in connect
    self._request_authentication()
  File "/home/frappe/frappe-bench/env/lib/python3.11/site-packages/pymysql/connections.py", line 957, in _request_authentication
    auth_packet = self._read_packet()
                  ^^^^^^^^^^^^^^^^^^^
  File "/home/frappe/frappe-bench/env/lib/python3.11/site-packages/pymysql/connections.py", line 775, in _read_packet
    packet.raise_for_error()
  File "/home/frappe/frappe-bench/env/lib/python3.11/site-packages/pymysql/protocol.py", line 219, in raise_for_error
    err.raise_mysql_exception(self._data)
  File "/home/frappe/frappe-bench/env/lib/python3.11/site-packages/pymysql/err.py", line 150, in raise_mysql_exception
    raise errorclass(errno, errval)
pymysql.err.OperationalError: (1045, "Access denied for user '_e1ef3e0c4bdfa786'@'172.18.0.4' (using password: YES)")
2025-06-23 07:05:04,810 ERROR scheduler Exception in Enqueue Events for Site site1.localhost
Traceback (most recent call last):
  File "/home/frappe/frappe-bench/apps/frappe/frappe/utils/scheduler.py", line 99, in enqueue_events_for_site
    if is_scheduler_inactive():
       ^^^^^^^^^^^^^^^^^^^^^^^
  File "/home/frappe/frappe-bench/apps/frappe/frappe/utils/scheduler.py", line 143, in is_scheduler_inactive
    if is_scheduler_disabled(verbose=verbose):
       ^^^^^^^^^^^^^^^^^^^^^^^^^^^^^^^^^^^^^^
  File "/home/frappe/frappe-bench/apps/frappe/frappe/utils/scheduler.py", line 156, in is_scheduler_disabled
    frappe.db.get_single_value("System Settings", "enable_scheduler")
  File "/home/frappe/frappe-bench/apps/frappe/frappe/database/database.py", line 837, in get_single_value
    ).run()
      ^^^^^
  File "/home/frappe/frappe-bench/apps/frappe/frappe/query_builder/utils.py", line 87, in execute_query
    result = frappe.db.sql(query, params, *args, **kwargs)  # nosemgrep
             ^^^^^^^^^^^^^^^^^^^^^^^^^^^^^^^^^^^^^^^^^^^^^
  File "/home/frappe/frappe-bench/apps/frappe/frappe/database/database.py", line 207, in sql
    self.connect()
  File "/home/frappe/frappe-bench/apps/frappe/frappe/database/database.py", line 112, in connect
    self._conn: "MariadbConnection" | "PostgresConnection" = self.get_connection()
                                                             ^^^^^^^^^^^^^^^^^^^^^
  File "/home/frappe/frappe-bench/apps/frappe/frappe/database/mariadb/database.py", line 108, in get_connection
    conn = self._get_connection()
           ^^^^^^^^^^^^^^^^^^^^^^
  File "/home/frappe/frappe-bench/apps/frappe/frappe/database/mariadb/database.py", line 114, in _get_connection
    return self.create_connection()
           ^^^^^^^^^^^^^^^^^^^^^^^^
  File "/home/frappe/frappe-bench/apps/frappe/frappe/database/mariadb/database.py", line 117, in create_connection
    return pymysql.connect(**self.get_connection_settings())
           ^^^^^^^^^^^^^^^^^^^^^^^^^^^^^^^^^^^^^^^^^^^^^^^^^
  File "/home/frappe/frappe-bench/env/lib/python3.11/site-packages/pymysql/connections.py", line 361, in __init__
    self.connect()
  File "/home/frappe/frappe-bench/env/lib/python3.11/site-packages/pymysql/connections.py", line 669, in connect
    self._request_authentication()
  File "/home/frappe/frappe-bench/env/lib/python3.11/site-packages/pymysql/connections.py", line 957, in _request_authentication
    auth_packet = self._read_packet()
                  ^^^^^^^^^^^^^^^^^^^
  File "/home/frappe/frappe-bench/env/lib/python3.11/site-packages/pymysql/connections.py", line 775, in _read_packet
    packet.raise_for_error()
  File "/home/frappe/frappe-bench/env/lib/python3.11/site-packages/pymysql/protocol.py", line 219, in raise_for_error
    err.raise_mysql_exception(self._data)
  File "/home/frappe/frappe-bench/env/lib/python3.11/site-packages/pymysql/err.py", line 150, in raise_mysql_exception
    raise errorclass(errno, errval)
pymysql.err.OperationalError: (1045, "Access denied for user '_e1ef3e0c4bdfa786'@'172.18.0.4' (using password: YES)")
2025-06-23 07:06:06,338 ERROR scheduler Exception in Enqueue Events for Site site1.localhost
Traceback (most recent call last):
  File "/home/frappe/frappe-bench/apps/frappe/frappe/utils/scheduler.py", line 99, in enqueue_events_for_site
    if is_scheduler_inactive():
       ^^^^^^^^^^^^^^^^^^^^^^^
  File "/home/frappe/frappe-bench/apps/frappe/frappe/utils/scheduler.py", line 143, in is_scheduler_inactive
    if is_scheduler_disabled(verbose=verbose):
       ^^^^^^^^^^^^^^^^^^^^^^^^^^^^^^^^^^^^^^
  File "/home/frappe/frappe-bench/apps/frappe/frappe/utils/scheduler.py", line 156, in is_scheduler_disabled
    frappe.db.get_single_value("System Settings", "enable_scheduler")
  File "/home/frappe/frappe-bench/apps/frappe/frappe/database/database.py", line 837, in get_single_value
    ).run()
      ^^^^^
  File "/home/frappe/frappe-bench/apps/frappe/frappe/query_builder/utils.py", line 87, in execute_query
    result = frappe.db.sql(query, params, *args, **kwargs)  # nosemgrep
             ^^^^^^^^^^^^^^^^^^^^^^^^^^^^^^^^^^^^^^^^^^^^^
  File "/home/frappe/frappe-bench/apps/frappe/frappe/database/database.py", line 207, in sql
    self.connect()
  File "/home/frappe/frappe-bench/apps/frappe/frappe/database/database.py", line 112, in connect
    self._conn: "MariadbConnection" | "PostgresConnection" = self.get_connection()
                                                             ^^^^^^^^^^^^^^^^^^^^^
  File "/home/frappe/frappe-bench/apps/frappe/frappe/database/mariadb/database.py", line 108, in get_connection
    conn = self._get_connection()
           ^^^^^^^^^^^^^^^^^^^^^^
  File "/home/frappe/frappe-bench/apps/frappe/frappe/database/mariadb/database.py", line 114, in _get_connection
    return self.create_connection()
           ^^^^^^^^^^^^^^^^^^^^^^^^
  File "/home/frappe/frappe-bench/apps/frappe/frappe/database/mariadb/database.py", line 117, in create_connection
    return pymysql.connect(**self.get_connection_settings())
           ^^^^^^^^^^^^^^^^^^^^^^^^^^^^^^^^^^^^^^^^^^^^^^^^^
  File "/home/frappe/frappe-bench/env/lib/python3.11/site-packages/pymysql/connections.py", line 361, in __init__
    self.connect()
  File "/home/frappe/frappe-bench/env/lib/python3.11/site-packages/pymysql/connections.py", line 669, in connect
    self._request_authentication()
  File "/home/frappe/frappe-bench/env/lib/python3.11/site-packages/pymysql/connections.py", line 957, in _request_authentication
    auth_packet = self._read_packet()
                  ^^^^^^^^^^^^^^^^^^^
  File "/home/frappe/frappe-bench/env/lib/python3.11/site-packages/pymysql/connections.py", line 775, in _read_packet
    packet.raise_for_error()
  File "/home/frappe/frappe-bench/env/lib/python3.11/site-packages/pymysql/protocol.py", line 219, in raise_for_error
    err.raise_mysql_exception(self._data)
  File "/home/frappe/frappe-bench/env/lib/python3.11/site-packages/pymysql/err.py", line 150, in raise_mysql_exception
    raise errorclass(errno, errval)
pymysql.err.OperationalError: (1045, "Access denied for user '_e1ef3e0c4bdfa786'@'172.18.0.4' (using password: YES)")
2025-06-23 07:18:14,036 ERROR scheduler Exception in Enqueue Events for Site site1.localhost
Traceback (most recent call last):
  File "/home/frappe/frappe-bench/apps/frappe/frappe/utils/scheduler.py", line 99, in enqueue_events_for_site
    if is_scheduler_inactive():
       ^^^^^^^^^^^^^^^^^^^^^^^
  File "/home/frappe/frappe-bench/apps/frappe/frappe/utils/scheduler.py", line 143, in is_scheduler_inactive
    if is_scheduler_disabled(verbose=verbose):
       ^^^^^^^^^^^^^^^^^^^^^^^^^^^^^^^^^^^^^^
  File "/home/frappe/frappe-bench/apps/frappe/frappe/utils/scheduler.py", line 156, in is_scheduler_disabled
    frappe.db.get_single_value("System Settings", "enable_scheduler")
  File "/home/frappe/frappe-bench/apps/frappe/frappe/database/database.py", line 837, in get_single_value
    ).run()
      ^^^^^
  File "/home/frappe/frappe-bench/apps/frappe/frappe/query_builder/utils.py", line 87, in execute_query
    result = frappe.db.sql(query, params, *args, **kwargs)  # nosemgrep
             ^^^^^^^^^^^^^^^^^^^^^^^^^^^^^^^^^^^^^^^^^^^^^
  File "/home/frappe/frappe-bench/apps/frappe/frappe/database/database.py", line 207, in sql
    self.connect()
  File "/home/frappe/frappe-bench/apps/frappe/frappe/database/database.py", line 112, in connect
    self._conn: "MariadbConnection" | "PostgresConnection" = self.get_connection()
                                                             ^^^^^^^^^^^^^^^^^^^^^
  File "/home/frappe/frappe-bench/apps/frappe/frappe/database/mariadb/database.py", line 108, in get_connection
    conn = self._get_connection()
           ^^^^^^^^^^^^^^^^^^^^^^
  File "/home/frappe/frappe-bench/apps/frappe/frappe/database/mariadb/database.py", line 114, in _get_connection
    return self.create_connection()
           ^^^^^^^^^^^^^^^^^^^^^^^^
  File "/home/frappe/frappe-bench/apps/frappe/frappe/database/mariadb/database.py", line 117, in create_connection
    return pymysql.connect(**self.get_connection_settings())
           ^^^^^^^^^^^^^^^^^^^^^^^^^^^^^^^^^^^^^^^^^^^^^^^^^
  File "/home/frappe/frappe-bench/env/lib/python3.11/site-packages/pymysql/connections.py", line 361, in __init__
    self.connect()
  File "/home/frappe/frappe-bench/env/lib/python3.11/site-packages/pymysql/connections.py", line 669, in connect
    self._request_authentication()
  File "/home/frappe/frappe-bench/env/lib/python3.11/site-packages/pymysql/connections.py", line 957, in _request_authentication
    auth_packet = self._read_packet()
                  ^^^^^^^^^^^^^^^^^^^
  File "/home/frappe/frappe-bench/env/lib/python3.11/site-packages/pymysql/connections.py", line 775, in _read_packet
    packet.raise_for_error()
  File "/home/frappe/frappe-bench/env/lib/python3.11/site-packages/pymysql/protocol.py", line 219, in raise_for_error
    err.raise_mysql_exception(self._data)
  File "/home/frappe/frappe-bench/env/lib/python3.11/site-packages/pymysql/err.py", line 150, in raise_mysql_exception
    raise errorclass(errno, errval)
pymysql.err.OperationalError: (1045, "Access denied for user '_e1ef3e0c4bdfa786'@'172.18.0.4' (using password: YES)")
2025-06-23 07:19:15,638 ERROR scheduler Exception in Enqueue Events for Site site1.localhost
Traceback (most recent call last):
  File "/home/frappe/frappe-bench/apps/frappe/frappe/utils/scheduler.py", line 99, in enqueue_events_for_site
    if is_scheduler_inactive():
       ^^^^^^^^^^^^^^^^^^^^^^^
  File "/home/frappe/frappe-bench/apps/frappe/frappe/utils/scheduler.py", line 143, in is_scheduler_inactive
    if is_scheduler_disabled(verbose=verbose):
       ^^^^^^^^^^^^^^^^^^^^^^^^^^^^^^^^^^^^^^
  File "/home/frappe/frappe-bench/apps/frappe/frappe/utils/scheduler.py", line 156, in is_scheduler_disabled
    frappe.db.get_single_value("System Settings", "enable_scheduler")
  File "/home/frappe/frappe-bench/apps/frappe/frappe/database/database.py", line 837, in get_single_value
    ).run()
      ^^^^^
  File "/home/frappe/frappe-bench/apps/frappe/frappe/query_builder/utils.py", line 87, in execute_query
    result = frappe.db.sql(query, params, *args, **kwargs)  # nosemgrep
             ^^^^^^^^^^^^^^^^^^^^^^^^^^^^^^^^^^^^^^^^^^^^^
  File "/home/frappe/frappe-bench/apps/frappe/frappe/database/database.py", line 207, in sql
    self.connect()
  File "/home/frappe/frappe-bench/apps/frappe/frappe/database/database.py", line 112, in connect
    self._conn: "MariadbConnection" | "PostgresConnection" = self.get_connection()
                                                             ^^^^^^^^^^^^^^^^^^^^^
  File "/home/frappe/frappe-bench/apps/frappe/frappe/database/mariadb/database.py", line 108, in get_connection
    conn = self._get_connection()
           ^^^^^^^^^^^^^^^^^^^^^^
  File "/home/frappe/frappe-bench/apps/frappe/frappe/database/mariadb/database.py", line 114, in _get_connection
    return self.create_connection()
           ^^^^^^^^^^^^^^^^^^^^^^^^
  File "/home/frappe/frappe-bench/apps/frappe/frappe/database/mariadb/database.py", line 117, in create_connection
    return pymysql.connect(**self.get_connection_settings())
           ^^^^^^^^^^^^^^^^^^^^^^^^^^^^^^^^^^^^^^^^^^^^^^^^^
  File "/home/frappe/frappe-bench/env/lib/python3.11/site-packages/pymysql/connections.py", line 361, in __init__
    self.connect()
  File "/home/frappe/frappe-bench/env/lib/python3.11/site-packages/pymysql/connections.py", line 669, in connect
    self._request_authentication()
  File "/home/frappe/frappe-bench/env/lib/python3.11/site-packages/pymysql/connections.py", line 957, in _request_authentication
    auth_packet = self._read_packet()
                  ^^^^^^^^^^^^^^^^^^^
  File "/home/frappe/frappe-bench/env/lib/python3.11/site-packages/pymysql/connections.py", line 775, in _read_packet
    packet.raise_for_error()
  File "/home/frappe/frappe-bench/env/lib/python3.11/site-packages/pymysql/protocol.py", line 219, in raise_for_error
    err.raise_mysql_exception(self._data)
  File "/home/frappe/frappe-bench/env/lib/python3.11/site-packages/pymysql/err.py", line 150, in raise_mysql_exception
    raise errorclass(errno, errval)
pymysql.err.OperationalError: (1045, "Access denied for user '_e1ef3e0c4bdfa786'@'172.18.0.4' (using password: YES)")
2025-06-23 07:20:17,122 ERROR scheduler Exception in Enqueue Events for Site site1.localhost
Traceback (most recent call last):
  File "/home/frappe/frappe-bench/apps/frappe/frappe/utils/scheduler.py", line 99, in enqueue_events_for_site
    if is_scheduler_inactive():
       ^^^^^^^^^^^^^^^^^^^^^^^
  File "/home/frappe/frappe-bench/apps/frappe/frappe/utils/scheduler.py", line 143, in is_scheduler_inactive
    if is_scheduler_disabled(verbose=verbose):
       ^^^^^^^^^^^^^^^^^^^^^^^^^^^^^^^^^^^^^^
  File "/home/frappe/frappe-bench/apps/frappe/frappe/utils/scheduler.py", line 156, in is_scheduler_disabled
    frappe.db.get_single_value("System Settings", "enable_scheduler")
  File "/home/frappe/frappe-bench/apps/frappe/frappe/database/database.py", line 837, in get_single_value
    ).run()
      ^^^^^
  File "/home/frappe/frappe-bench/apps/frappe/frappe/query_builder/utils.py", line 87, in execute_query
    result = frappe.db.sql(query, params, *args, **kwargs)  # nosemgrep
             ^^^^^^^^^^^^^^^^^^^^^^^^^^^^^^^^^^^^^^^^^^^^^
  File "/home/frappe/frappe-bench/apps/frappe/frappe/database/database.py", line 207, in sql
    self.connect()
  File "/home/frappe/frappe-bench/apps/frappe/frappe/database/database.py", line 112, in connect
    self._conn: "MariadbConnection" | "PostgresConnection" = self.get_connection()
                                                             ^^^^^^^^^^^^^^^^^^^^^
  File "/home/frappe/frappe-bench/apps/frappe/frappe/database/mariadb/database.py", line 108, in get_connection
    conn = self._get_connection()
           ^^^^^^^^^^^^^^^^^^^^^^
  File "/home/frappe/frappe-bench/apps/frappe/frappe/database/mariadb/database.py", line 114, in _get_connection
    return self.create_connection()
           ^^^^^^^^^^^^^^^^^^^^^^^^
  File "/home/frappe/frappe-bench/apps/frappe/frappe/database/mariadb/database.py", line 117, in create_connection
    return pymysql.connect(**self.get_connection_settings())
           ^^^^^^^^^^^^^^^^^^^^^^^^^^^^^^^^^^^^^^^^^^^^^^^^^
  File "/home/frappe/frappe-bench/env/lib/python3.11/site-packages/pymysql/connections.py", line 361, in __init__
    self.connect()
  File "/home/frappe/frappe-bench/env/lib/python3.11/site-packages/pymysql/connections.py", line 669, in connect
    self._request_authentication()
  File "/home/frappe/frappe-bench/env/lib/python3.11/site-packages/pymysql/connections.py", line 957, in _request_authentication
    auth_packet = self._read_packet()
                  ^^^^^^^^^^^^^^^^^^^
  File "/home/frappe/frappe-bench/env/lib/python3.11/site-packages/pymysql/connections.py", line 775, in _read_packet
    packet.raise_for_error()
  File "/home/frappe/frappe-bench/env/lib/python3.11/site-packages/pymysql/protocol.py", line 219, in raise_for_error
    err.raise_mysql_exception(self._data)
  File "/home/frappe/frappe-bench/env/lib/python3.11/site-packages/pymysql/err.py", line 150, in raise_mysql_exception
    raise errorclass(errno, errval)
pymysql.err.OperationalError: (1045, "Access denied for user '_e1ef3e0c4bdfa786'@'172.18.0.4' (using password: YES)")
2025-06-23 07:21:18,623 ERROR scheduler Exception in Enqueue Events for Site site1.localhost
Traceback (most recent call last):
  File "/home/frappe/frappe-bench/apps/frappe/frappe/utils/scheduler.py", line 99, in enqueue_events_for_site
    if is_scheduler_inactive():
       ^^^^^^^^^^^^^^^^^^^^^^^
  File "/home/frappe/frappe-bench/apps/frappe/frappe/utils/scheduler.py", line 143, in is_scheduler_inactive
    if is_scheduler_disabled(verbose=verbose):
       ^^^^^^^^^^^^^^^^^^^^^^^^^^^^^^^^^^^^^^
  File "/home/frappe/frappe-bench/apps/frappe/frappe/utils/scheduler.py", line 156, in is_scheduler_disabled
    frappe.db.get_single_value("System Settings", "enable_scheduler")
  File "/home/frappe/frappe-bench/apps/frappe/frappe/database/database.py", line 837, in get_single_value
    ).run()
      ^^^^^
  File "/home/frappe/frappe-bench/apps/frappe/frappe/query_builder/utils.py", line 87, in execute_query
    result = frappe.db.sql(query, params, *args, **kwargs)  # nosemgrep
             ^^^^^^^^^^^^^^^^^^^^^^^^^^^^^^^^^^^^^^^^^^^^^
  File "/home/frappe/frappe-bench/apps/frappe/frappe/database/database.py", line 207, in sql
    self.connect()
  File "/home/frappe/frappe-bench/apps/frappe/frappe/database/database.py", line 112, in connect
    self._conn: "MariadbConnection" | "PostgresConnection" = self.get_connection()
                                                             ^^^^^^^^^^^^^^^^^^^^^
  File "/home/frappe/frappe-bench/apps/frappe/frappe/database/mariadb/database.py", line 108, in get_connection
    conn = self._get_connection()
           ^^^^^^^^^^^^^^^^^^^^^^
  File "/home/frappe/frappe-bench/apps/frappe/frappe/database/mariadb/database.py", line 114, in _get_connection
    return self.create_connection()
           ^^^^^^^^^^^^^^^^^^^^^^^^
  File "/home/frappe/frappe-bench/apps/frappe/frappe/database/mariadb/database.py", line 117, in create_connection
    return pymysql.connect(**self.get_connection_settings())
           ^^^^^^^^^^^^^^^^^^^^^^^^^^^^^^^^^^^^^^^^^^^^^^^^^
  File "/home/frappe/frappe-bench/env/lib/python3.11/site-packages/pymysql/connections.py", line 361, in __init__
    self.connect()
  File "/home/frappe/frappe-bench/env/lib/python3.11/site-packages/pymysql/connections.py", line 669, in connect
    self._request_authentication()
  File "/home/frappe/frappe-bench/env/lib/python3.11/site-packages/pymysql/connections.py", line 957, in _request_authentication
    auth_packet = self._read_packet()
                  ^^^^^^^^^^^^^^^^^^^
  File "/home/frappe/frappe-bench/env/lib/python3.11/site-packages/pymysql/connections.py", line 775, in _read_packet
    packet.raise_for_error()
  File "/home/frappe/frappe-bench/env/lib/python3.11/site-packages/pymysql/protocol.py", line 219, in raise_for_error
    err.raise_mysql_exception(self._data)
  File "/home/frappe/frappe-bench/env/lib/python3.11/site-packages/pymysql/err.py", line 150, in raise_mysql_exception
    raise errorclass(errno, errval)
pymysql.err.OperationalError: (1045, "Access denied for user '_e1ef3e0c4bdfa786'@'172.18.0.4' (using password: YES)")
2025-06-23 07:22:20,848 ERROR scheduler Exception in Enqueue Events for Site site1.localhost
Traceback (most recent call last):
  File "/home/frappe/frappe-bench/apps/frappe/frappe/utils/scheduler.py", line 99, in enqueue_events_for_site
    if is_scheduler_inactive():
       ^^^^^^^^^^^^^^^^^^^^^^^
  File "/home/frappe/frappe-bench/apps/frappe/frappe/utils/scheduler.py", line 143, in is_scheduler_inactive
    if is_scheduler_disabled(verbose=verbose):
       ^^^^^^^^^^^^^^^^^^^^^^^^^^^^^^^^^^^^^^
  File "/home/frappe/frappe-bench/apps/frappe/frappe/utils/scheduler.py", line 156, in is_scheduler_disabled
    frappe.db.get_single_value("System Settings", "enable_scheduler")
  File "/home/frappe/frappe-bench/apps/frappe/frappe/database/database.py", line 837, in get_single_value
    ).run()
      ^^^^^
  File "/home/frappe/frappe-bench/apps/frappe/frappe/query_builder/utils.py", line 87, in execute_query
    result = frappe.db.sql(query, params, *args, **kwargs)  # nosemgrep
             ^^^^^^^^^^^^^^^^^^^^^^^^^^^^^^^^^^^^^^^^^^^^^
  File "/home/frappe/frappe-bench/apps/frappe/frappe/database/database.py", line 207, in sql
    self.connect()
  File "/home/frappe/frappe-bench/apps/frappe/frappe/database/database.py", line 112, in connect
    self._conn: "MariadbConnection" | "PostgresConnection" = self.get_connection()
                                                             ^^^^^^^^^^^^^^^^^^^^^
  File "/home/frappe/frappe-bench/apps/frappe/frappe/database/mariadb/database.py", line 108, in get_connection
    conn = self._get_connection()
           ^^^^^^^^^^^^^^^^^^^^^^
  File "/home/frappe/frappe-bench/apps/frappe/frappe/database/mariadb/database.py", line 114, in _get_connection
    return self.create_connection()
           ^^^^^^^^^^^^^^^^^^^^^^^^
  File "/home/frappe/frappe-bench/apps/frappe/frappe/database/mariadb/database.py", line 117, in create_connection
    return pymysql.connect(**self.get_connection_settings())
           ^^^^^^^^^^^^^^^^^^^^^^^^^^^^^^^^^^^^^^^^^^^^^^^^^
  File "/home/frappe/frappe-bench/env/lib/python3.11/site-packages/pymysql/connections.py", line 361, in __init__
    self.connect()
  File "/home/frappe/frappe-bench/env/lib/python3.11/site-packages/pymysql/connections.py", line 669, in connect
    self._request_authentication()
  File "/home/frappe/frappe-bench/env/lib/python3.11/site-packages/pymysql/connections.py", line 957, in _request_authentication
    auth_packet = self._read_packet()
                  ^^^^^^^^^^^^^^^^^^^
  File "/home/frappe/frappe-bench/env/lib/python3.11/site-packages/pymysql/connections.py", line 775, in _read_packet
    packet.raise_for_error()
  File "/home/frappe/frappe-bench/env/lib/python3.11/site-packages/pymysql/protocol.py", line 219, in raise_for_error
    err.raise_mysql_exception(self._data)
  File "/home/frappe/frappe-bench/env/lib/python3.11/site-packages/pymysql/err.py", line 150, in raise_mysql_exception
    raise errorclass(errno, errval)
pymysql.err.OperationalError: (1045, "Access denied for user '_e1ef3e0c4bdfa786'@'172.18.0.4' (using password: YES)")
